Workbook
Name ListaActivos: Activos!$A$5:$A$104

Sheet Guía de uso
A1: GUÍA RÁPIDA DE USO – REGISTRO DE INVERSIONES V4
A2: Registra solo hechos reales. No edites Resumen ni Posiciones. Rendimiento conserva snapshots históricos.
A4: Paso / indicador | B4: Hoja / concepto | C4: Qué significa / qué haces | D4: Ejemplo | E4: ¿Editable? | F4: Regla
A5: 1 | B5: Activos | C5: Crea cada ticker una sola vez | D5: IVV / VXUS / BTC | E5: Sí | F5: Define tipo, moneda y objetivo
A6: 2 | B6: Aportes | C6: Registra dinero que sale de tu bolsillo | D6: $200 → $195.58 | E6: Sí | F6: Una fila por fondeo
A7: 3 | B7: Transacciones | C7: Registra COMPRA o VENTA | D7: COMPRA IVV $112 | E7: Sí | F7: Monto operación = valor real del broker
A8: 4 | B8: Referidos | C8: Registra la cantidad recibida y conserva precio/valor del día de entrega; el valor actual se recalcula con mercado. | D8: BTC: 0.00001196; recibido $1.00 | E8: Sí | F8: No aumenta aporte propio; no cambies cantidad, precio al recibir ni valor recibido.
A9: 5 | B9: Dividendos | C9: Registra bruto, retenciones y neto | D9: IVV/VXUS | E9: Sí | F9: Si reinviertes, crea además una COMPRA
A10: 6 | B10: Precios | C10: Agrega precio histórico | D10: 22/10 IVV $... | E10: Sí | F10: No sobrescribas precios anteriores
A11: 7 | B11: Posiciones | C11: Revisa tenencias consolidadas | D11: Comprado - vendido + referido | E11: No | F11: Todo se calcula
A12: 8 | B12: Resumen | C12: Interpreta patrimonio y efectivo | D12: Resultado vs bolsillo | E12: No | F12: Todo se calcula
A13: 9 | B13: Rendimiento | C13: Guarda fotografías del portafolio | D13: Fin de mes | E13: Sí, valores | F13: No enlaces snapshots a precios futuros
A15: CÓMO REGISTRAR UN APORTE
A16: Aporte real | B16: Dinero que salió de tu bolsillo | C16: $200
A17: Neto broker | B17: Dinero que realmente llegó | C17: $195.58
A18: Costo fondeo | B18: Aporte - neto | C18: $4.42
A20: CÓMO REGISTRAR UNA TRANSACCIÓN
A21: Movimiento | B21: COMPRA o VENTA | C21: COMPRA
A22: Cantidad | B22: Unidades ejecutadas | C22: 0.14553 IVV
A23: Precio ejecución | B23: Precio por unidad | C23: $769.57
A24: Monto operación | B24: Importe real antes de comisión | C24: $112.00
A25: Comisión | B25: Costo cobrado por el broker | C25: $0.15
A26: Efectivo neto | B26: Compra resta; venta suma | C26: -$112.15
A28: CÓMO LEER POSICIONES
A29: Cantidad actual | B29: Comprado - vendido + referido
A30: Costo promedio compra | B30: Costo total compras / cantidad comprada
A31: Valor actual | B31: Cantidad actual × último precio
A32: G/P no realizada | B32: Movimiento de mercado de compras aún mantenidas
A33: Resultado patrimonial | B33: Valor actual - costo base de compras. Los referidos suman patrimonio porque su costo desde bolsillo es $0; no confundir con el rendimiento del referido.
A34: Peso actual | B34: Valor del activo / valor total de posiciones
A35: Diferencia | B35: Peso actual - objetivo
A37: CÓMO LEER EL RESUMEN
A38: Aportado de bolsillo | B38: Todo el dinero que tú has puesto
A39: Neto broker | B39: Lo que llegó después de fondeo
A40: Fricción total | B40: Costos de fondeo + comisiones
A41: Efectivo | B41: Neto broker + flujos de transacciones + dividendos
A42: Valor posiciones | B42: Valor actual de todos los activos, incluidos referidos
A43: Valor total | B43: Efectivo + valor posiciones
A44: Resultado vs bolsillo | B44: Valor total - dinero aportado
A45: Rentabilidad vs bolsillo | B45: Resultado / dinero aportado
...

Sheet Resumen
A1: CONTROL DE INVERSIONES - RESUMEN
A2: Vista automática. Registra datos en Activos, Aportes, Transacciones, Referidos, Dividendos y Precios.
A4: Dinero aportado de tu bolsillo ($) | B4: =SUM(Aportes!B5:B204) -> 575
A5: Neto que llegó al broker ($) | B5: =SUM(Aportes!C5:C204) -> 559.13
A6: Costos de fondeo / conversión ($) | B6: =SUM(Aportes!D5:D204) -> 15.87
A7: Monto bruto comprado ($) | B7: =SUMIFS(Transacciones!G5:G1004,Transacciones!D5:D1004,"COMPRA") -> 503.07
A8: Comisiones de trading acumuladas ($) | B8: =SUM(Transacciones!H5:H1004) -> 1.02
A9: Fricción total acumulada ($) | B9: =B6+B8 -> 16.89
A10: Dividendos netos recibidos ($) | B10: =SUM(Dividendos!F5:F204) -> 0
A11: Efectivo disponible en broker ($) | B11: =B5+SUM(Transacciones!I5:I1004)+B10 -> 55.04
A12: Valor actual de posiciones ($) | B12: =SUM(Posiciones!N5:N104) -> 502.77495
A13: Valor actual de referidos incluido arriba ($) | B13: =SUM(Referidos!H5:H204) -> 0.98061152
A14: Valor total del portafolio ($) | B14: =B11+B12 -> 557.81495
A15: G/P no realizada de compras ($) | B15: =SUM(Posiciones!P5:P104) -> -2.2956634
A16: Variación de referidos desde entrega ($) | B16: =SUM(Referidos!I5:I204) -> -0.019388477
A17: Resultado total vs bolsillo ($) | B17: =B14-B4 -> -17.185052
A18: Rentabilidad total vs bolsillo (%) | B18: =IFERROR(B17/B4,0) -> -0.029887047
A20: LECTURA RÁPIDA
A21: Resultado vs bolsillo | B21: Patrimonio actual menos todo el dinero que salió de tu bolsillo.
A22: G/P no realizada | B22: Movimiento de mercado sobre las unidades compradas que siguen en cartera.
A23: Efectivo disponible | B23: Neto recibido + flujos de compras/ventas + dividendos netos.
A24: Referidos | B24: Cantidad y valor recibido son históricos; precio y valor actual cambian con el mercado. No aumenta tus aportes.
A26: CONTROL DE PRECIOS
A27: Última fecha registrada | B27: =IFERROR(MAX(Precios!A5:A2004),"") -> 46314
A28: Advertencia | B28: La valoración utiliza el último precio registrado por ticker; si está desactualizado, el valor del portafolio también lo estará.

Sheet Activos
A1: CATÁLOGO DE ACTIVOS
A2: Registra cada activo una sola vez. Tipo, moneda y objetivo se reutilizan en el resto del libro.
A4: Ticker | B4: Nombre | C4: Tipo | D4: Moneda | E4: Objetivo % | F4: Activo? | G4: Nota
A5: IVV | B5: iShares Core S&P 500 ETF | C5: ETF | D5: USD | E5: 0.85 | F5: SI | G5: Base principal
A6: VXUS | B6: Vanguard Total International Stock ETF | C6: ETF | D6: USD | E6: 0.1 | F6: SI | G6: Diversificación internacional
A7: BTC | B7: Bitcoin | C7: CRIPTO | D7: USD | E7: 0.05 | F7: SI | G7: Criptoactivo

Sheet Aportes
A1: APORTES DE DINERO
A2: Una fila = una entrada de dinero desde tu bolsillo. El costo se calcula como aporte real menos neto recibido.
A4: Fecha | B4: Aporte real ($) | C4: Neto broker ($) | D4: Costo fondeo ($) | E4: Método / ruta | F4: Nota
A5: 46308 | B5: 125 | C5: 120.22 | D5: =IF(OR(B5="",C5=""),"",B5-C5) -> 4.78 | E5: Binance USDT → ERC20 → Hapi | F5: Primer aporte
A6: 46314 | B6: 250 | C6: 243.33 | D6: =IF(OR(B6="",C6=""),"",B6-C6) -> 6.67 | E6: Binance USDT → ERC20 → Hapi | F6: Segundo aporte
A7: 46316 | B7: 200 | C7: 195.58 | D7: =IF(OR(B7="",C7=""),"",B7-C7) -> 4.42 | E7: Binance USDT → ERC20 → Hapi | F7: Tercer aporte
D8: =IF(OR(B8="",C8=""),"",B8-C8)
D9: =IF(OR(B9="",C9=""),"",B9-C9)
D10: =IF(OR(B10="",C10=""),"",B10-C10)
D11: =IF(OR(B11="",C11=""),"",B11-C11)
D12: =IF(OR(B12="",C12=""),"",B12-C12)
D13: =IF(OR(B13="",C13=""),"",B13-C13)
D14: =IF(OR(B14="",C14=""),"",B14-C14)
D15: =IF(OR(B15="",C15=""),"",B15-C15)
D16: =IF(OR(B16="",C16=""),"",B16-C16)
D17: =IF(OR(B17="",C17=""),"",B17-C17)
D18: =IF(OR(B18="",C18=""),"",B18-C18)
D19: =IF(OR(B19="",C19=""),"",B19-C19)
... D204: =IF(OR(B204="",C204=""),"",B204-C204)

Sheet Transacciones
A1: TRANSACCIONES DE ACTIVOS
A2: Una fila = una compra o venta. El tipo se obtiene de Activos. Monto operación = importe real del broker antes de comisión.
A4: Fecha | B4: Activo | C4: Tipo activo | D4: Movimiento | E4: Cantidad | F4: Precio ejecución ($) | G4: Monto operación ($) | H4: Comisión ($) | I4: Efectivo neto ($) | J4: Nota
A5: 46308 | B5: IVV | C5: =IFERROR(VLOOKUP(B5,Activos!$A$5:$C$104,3,FALSE),"") -> ETF | D5: COMPRA | E5: 0.15368 | F5: 781.28 | G5: 120.07 | H5: 0.15 | I5: =IF(OR(D5="",G5=""),"",IF(D5="COMPRA",-G5-IF(H5="",0,H5),IF(D5="VENTA",G5-IF(H5="",0,H5),""))) -> -120.22 | J5: Primera compra IVV
A6: 46314 | B6: IVV | C6: =IFERROR(VLOOKUP(B6,Activos!$A$5:$C$104,3,FALSE),"") -> ETF | D6: COMPRA | E6: 0.24387 | F6: 770.89 | G6: 188 | H6: 0.15 | I6: =IF(OR(D6="",G6=""),"",IF(D6="COMPRA",-G6-IF(H6="",0,H6),IF(D6="VENTA",G6-IF(H6="",0,H6),""))) -> -188.15 | J6: Segunda compra IVV
A7: 46314 | B7: VXUS | C7: =IFERROR(VLOOKUP(B7,Activos!$A$5:$C$104,3,FALSE),"") -> ETF | D7: COMPRA | E7: 0.43171 | F7: 83.38 | G7: 36 | H7: 0.15 | I7: =IF(OR(D7="",G7=""),"",IF(D7="COMPRA",-G7-IF(H7="",0,H7),IF(D7="VENTA",G7-IF(H7="",0,H7),""))) -> -36.15 | J7: Primera compra VXUS
A8: 46314 | B8: BTC | C8: =IFERROR(VLOOKUP(B8,Activos!$A$5:$C$104,3,FALSE),"") -> CRIPTO | D8: COMPRA | E8: 0.00020734 | F8: 81990.93 | G8: 17 | H8: 0.17 | I8: =IF(OR(D8="",G8=""),"",IF(D8="COMPRA",-G8-IF(H8="",0,H8),IF(D8="VENTA",G8-IF(H8="",0,H8),""))) -> -17.17 | J8: Compra bit Coin
A9: 46317 | B9: IVV | C9: =IFERROR(VLOOKUP(B9,Activos!$A$5:$C$104,3,FALSE),"") -> ETF | D9: COMPRA | E9: 0.14553 | F9: 769.57 | G9: 112 | H9: 0.15 | I9: =IF(OR(D9="",G9=""),"",IF(D9="COMPRA",-G9-IF(H9="",0,H9),IF(D9="VENTA",G9-IF(H9="",0,H9),""))) -> -112.15 | J9: Compra IVV
A10: 46317 | B10: VXUS | C10: =IFERROR(VLOOKUP(B10,Activos!$A$5:$C$104,3,FALSE),"") -> ETF | D10: COMPRA | E10: 0.24102 | F10: 82.97 | G10: 20 | H10: 0.15 | I10: =IF(OR(D10="",G10=""),"",IF(D10="COMPRA",-G10-IF(H10="",0,H10),IF(D10="VENTA",G10-IF(H10="",0,H10),""))) -> -20.15 | J10: Compra VXUS
A11: 46317 | B11: BTC | C11: =IFERROR(VLOOKUP(B11,Activos!$A$5:$C$104,3,FALSE),"") -> CRIPTO | D11: COMPRA | E11: 0.00012254 | F11: 81606 | G11: 10 | H11: 0.1 | I11: =IF(OR(D11="",G11=""),"",IF(D11="COMPRA",-G11-IF(H11="",0,H11),IF(D11="VENTA",G11-IF(H11="",0,H11),""))) -> -10.1 | J11: Compra BTC
C12: =IFERROR(VLOOKUP(B12,Activos!$A$5:$C$104,3,FALSE),"") | I12: =IF(OR(D12="",G12=""),"",IF(D12="COMPRA",-G12-IF(H12="",0,H12),IF(D12="VENTA",G12-IF(H12="",0,H12),"")))
C13: =IFERROR(VLOOKUP(B13,Activos!$A$5:$C$104,3,FALSE),"") | I13: =IF(OR(D13="",G13=""),"",IF(D13="COMPRA",-G13-IF(H13="",0,H13),IF(D13="VENTA",G13-IF(H13="",0,H13),"")))
C14: =IFERROR(VLOOKUP(B14,Activos!$A$5:$C$104,3,FALSE),"") | I14: =IF(OR(D14="",G14=""),"",IF(D14="COMPRA",-G14-IF(H14="",0,H14),IF(D14="VENTA",G14-IF(H14="",0,H14),"")))
C15: =IFERROR(VLOOKUP(B15,Activos!$A$5:$C$104,3,FALSE),"") | I15: =IF(OR(D15="",G15=""),"",IF(D15="COMPRA",-G15-IF(H15="",0,H15),IF(D15="VENTA",G15-IF(H15="",0,H15),"")))
C16: =IFERROR(VLOOKUP(B16,Activos!$A$5:$C$104,3,FALSE),"") | I16: =IF(OR(D16="",G16=""),"",IF(D16="COMPRA",-G16-IF(H16="",0,H16),IF(D16="VENTA",G16-IF(H16="",0,H16),"")))
C17: =IFERROR(VLOOKUP(B17,Activos!$A$5:$C$104,3,FALSE),"") | I17: =IF(OR(D17="",G17=""),"",IF(D17="COMPRA",-G17-IF(H17="",0,H17),IF(D17="VENTA",G17-IF(H17="",0,H17),"")))
C18: =IFERROR(VLOOKUP(B18,Activos!$A$5:$C$104,3,FALSE),"") | I18: =IF(OR(D18="",G18=""),"",IF(D18="COMPRA",-G18-IF(H18="",0,H18),IF(D18="VENTA",G18-IF(H18="",0,H18),"")))
C19: =IFERROR(VLOOKUP(B19,Activos!$A$5:$C$104,3,FALSE),"") | I19: =IF(OR(D19="",G19=""),"",IF(D19="COMPRA",-G19-IF(H19="",0,H19),IF(D19="VENTA",G19-IF(H19="",0,H19),"")))
C20: =IFERROR(VLOOKUP(B20,Activos!$A$5:$C$104,3,FALSE),"") | I20: =IF(OR(D20="",G20=""),"",IF(D20="COMPRA",-G20-IF(H20="",0,H20),IF(D20="VENTA",G20-IF(H20="",0,H20),"")))
C21: =IFERROR(VLOOKUP(B21,Activos!$A$5:$C$104,3,FALSE),"") | I21: =IF(OR(D21="",G21=""),"",IF(D21="COMPRA",-G21-IF(H21="",0,H21),IF(D21="VENTA",G21-IF(H21="",0,H21),"")))
C22: =IFERROR(VLOOKUP(B22,Activos!$A$5:$C$104,3,FALSE),"") | I22: =IF(OR(D22="",G22=""),"",IF(D22="COMPRA",-G22-IF(H22="",0,H22),IF(D22="VENTA",G22-IF(H22="",0,H22),"")))
C23: =IFERROR(VLOOKUP(B23,Activos!$A$5:$C$104,3,FALSE),"") | I23: =IF(OR(D23="",G23=""),"",IF(D23="COMPRA",-G23-IF(H23="",0,H23),IF(D23="VENTA",G23-IF(H23="",0,H23),"")))
... C1004: =IFERROR(VLOOKUP(B1004,Activos!$A$5:$C$104,3,FALSE),"") | I1004: =IF(OR(D1004="",G1004=""),"",IF(D1004="COMPRA",-G1004-IF(H1004="",0,H1004),IF(D1004="VENTA",G1004-IF(H1004="",0,H1004),"")))

Sheet Referidos
A1: REFERIDOS / PROMOCIONES
A2: Una fila = un activo recibido sin dinero de tu bolsillo. La cantidad y el valor recibido son históricos; el precio y valor actuales cambian con el mercado.
A4: Fecha | B4: Origen / tipo | C4: Activo | D4: Cantidad | E4: Precio al recibir ($) | F4: Valor recibido ($) | G4: Precio actual ($) | H4: Valor actual ($) | I4: Variación desde entrega ($) | J4: Rendimiento desde entrega (%) | K4: Costo desde bolsillo ($) | L4: Nota
A5: 46308 | B5: Referido | C5: BTC | D5: 1.196e-05 | E5: 83580.27 | F5: 1 | G5: =IF(C5="","",IFERROR(LOOKUP(2,1/(Precios!$B$5:$B$2004=C5),Precios!$C$5:$C$2004),0)) -> 81990.93 | H5: =IF(D5="","",D5*G5) -> 0.98061152 | I5: =IF(OR(H5="",F5=""),"",H5-F5) -> -0.019388477 | J5: =IFERROR(I5/F5,0) -> -0.019388477 | K5: 0 | L5: Premio Hapi por referido: $1.00 en BTC (13 oct 2026)
E6: =IF(C6="","",IFERROR(LOOKUP(2,1/(Precios!$B$5:$B$2004=C6),Precios!$C$5:$C$2004),0)) | F6: =IF(D6="","",D6*E6) | G6: =IF(C6="","",IFERROR(LOOKUP(2,1/(Precios!$B$5:$B$2004=C6),Precios!$C$5:$C$2004),0)) | H6: =IF(D6="","",D6*G6) | I6: =IF(OR(H6="",F6=""),"",H6-F6) | J6: =IFERROR(I6/F6,0) -> 0 | K6: 0
E7: =IF(C7="","",IFERROR(LOOKUP(2,1/(Precios!$B$5:$B$2004=C7),Precios!$C$5:$C$2004),0)) | F7: =IF(D7="","",D7*E7) | G7: =IF(C7="","",IFERROR(LOOKUP(2,1/(Precios!$B$5:$B$2004=C7),Precios!$C$5:$C$2004),0)) | H7: =IF(D7="","",D7*G7) | I7: =IF(OR(H7="",F7=""),"",H7-F7) | J7: =IFERROR(I7/F7,0) -> 0 | K7: 0
E8: =IF(C8="","",IFERROR(LOOKUP(2,1/(Precios!$B$5:$B$2004=C8),Precios!$C$5:$C$2004),0)) | F8: =IF(D8="","",D8*E8) | G8: =IF(C8="","",IFERROR(LOOKUP(2,1/(Precios!$B$5:$B$2004=C8),Precios!$C$5:$C$2004),0)) | H8: =IF(D8="","",D8*G8) | I8: =IF(OR(H8="",F8=""),"",H8-F8) | J8: =IFERROR(I8/F8,0) -> 0 | K8: 0
E9: =IF(C9="","",IFERROR(LOOKUP(2,1/(Precios!$B$5:$B$2004=C9),Precios!$C$5:$C$2004),0)) | F9: =IF(D9="","",D9*E9) | G9: =IF(C9="","",IFERROR(LOOKUP(2,1/(Precios!$B$5:$B$2004=C9),Precios!$C$5:$C$2004),0)) | H9: =IF(D9="","",D9*G9) | I9: =IF(OR(H9="",F9=""),"",H9-F9) | J9: =IFERROR(I9/F9,0) -> 0 | K9: 0
E10: =IF(C10="","",IFERROR(LOOKUP(2,1/(Precios!$B$5:$B$2004=C10),Precios!$C$5:$C$2004),0)) | F10: =IF(D10="","",D10*E10) | G10: =IF(C10="","",IFERROR(LOOKUP(2,1/(Precios!$B$5:$B$2004=C10),Precios!$C$5:$C$2004),0)) | H10: =IF(D10="","",D10*G10) | I10: =IF(OR(H10="",F10=""),"",H10-F10) | J10: =IFERROR(I10/F10,0) -> 0 | K10: 0
E11: =IF(C11="","",IFERROR(LOOKUP(2,1/(Precios!$B$5:$B$2004=C11),Precios!$C$5:$C$2004),0)) | F11: =IF(D11="","",D11*E11) | G11: =IF(C11="","",IFERROR(LOOKUP(2,1/(Precios!$B$5:$B$2004=C11),Precios!$C$5:$C$2004),0)) | H11: =IF(D11="","",D11*G11) | I11: =IF(OR(H11="",F11=""),"",H11-F11) | J11: =IFERROR(I11/F11,0) -> 0 | K11: 0
E12: =IF(C12="","",IFERROR(LOOKUP(2,1/(Precios!$B$5:$B$2004=C12),Precios!$C$5:$C$2004),0)) | F12: =IF(D12="","",D12*E12) | G12: =IF(C12="","",IFERROR(LOOKUP(2,1/(Precios!$B$5:$B$2004=C12),Precios!$C$5:$C$2004),0)) | H12: =IF(D12="","",D12*G12) | I12: =IF(OR(H12="",F12=""),"",H12-F12) | J12: =IFERROR(I12/F12,0) -> 0 | K12: 0
E13: =IF(C13="","",IFERROR(LOOKUP(2,1/(Precios!$B$5:$B$2004=C13),Precios!$C$5:$C$2004),0)) | F13: =IF(D13="","",D13*E13) | G13: =IF(C13="","",IFERROR(LOOKUP(2,1/(Precios!$B$5:$B$2004=C13),Precios!$C$5:$C$2004),0)) | H13: =IF(D13="","",D13*G13) | I13: =IF(OR(H13="",F13=""),"",H13-F13) | J13: =IFERROR(I13/F13,0) -> 0 | K13: 0
E14: =IF(C14="","",IFERROR(LOOKUP(2,1/(Precios!$B$5:$B$2004=C14),Precios!$C$5:$C$2004),0)) | F14: =IF(D14="","",D14*E14) | G14: =IF(C14="","",IFERROR(LOOKUP(2,1/(Precios!$B$5:$B$2004=C14),Precios!$C$5:$C$2004),0)) | H14: =IF(D14="","",D14*G14) | I14: =IF(OR(H14="",F14=""),"",H14-F14) | J14: =IFERROR(I14/F14,0) -> 0 | K14: 0
E15: =IF(C15="","",IFERROR(LOOKUP(2,1/(Precios!$B$5:$B$2004=C15),Precios!$C$5:$C$2004),0)) | F15: =IF(D15="","",D15*E15) | G15: =IF(C15="","",IFERROR(LOOKUP(2,1/(Precios!$B$5:$B$2004=C15),Precios!$C$5:$C$2004),0)) | H15: =IF(D15="","",D15*G15) | I15: =IF(OR(H15="",F15=""),"",H15-F15) | J15: =IFERROR(I15/F15,0) -> 0 | K15: 0
E16: =IF(C16="","",IFERROR(LOOKUP(2,1/(Precios!$B$5:$B$2004=C16),Precios!$C$5:$C$2004),0)) | F16: =IF(D16="","",D16*E16) | G16: =IF(C16="","",IFERROR(LOOKUP(2,1/(Precios!$B$5:$B$2004=C16),Precios!$C$5:$C$2004),0)) | H16: =IF(D16="","",D16*G16) | I16: =IF(OR(H16="",F16=""),"",H16-F16) | J16: =IFERROR(I16/F16,0) -> 0 | K16: 0
E17: =IF(C17="","",IFERROR(LOOKUP(2,1/(Precios!$B$5:$B$2004=C17),Precios!$C$5:$C$2004),0)) | F17: =IF(D17="","",D17*E17) | G17: =IF(C17="","",IFERROR(LOOKUP(2,1/(Precios!$B$5:$B$2004=C17),Precios!$C$5:$C$2004),0)) | H17: =IF(D17="","",D17*G17) | I17: =IF(OR(H17="",F17=""),"",H17-F17) | J17: =IFERROR(I17/F17,0) -> 0 | K17: 0
... E204: =IF(C204="","",IFERROR(LOOKUP(2,1/(Precios!$B$5:$B$2004=C204),Precios!$C$5:$C$2004),0)) | F204: =IF(D204="","",D204*E204) | G204: =IF(C204="","",IFERROR(LOOKUP(2,1/(Precios!$B$5:$B$2004=C204),Precios!$C$5:$C$2004),0)) | H204: =IF(D204="","",D204*G204) | I204: =IF(OR(H204="",F204=""),"",H204-F204) | J204: =IFERROR(I204/F204,0) -> 0 | K204: 0

Sheet Dividendos
A1: DIVIDENDOS / DISTRIBUCIONES
A2: El neto recibido aumenta efectivo. Si reinviertes, registra además una COMPRA en Transacciones; no se descuenta dos veces.
A4: Fecha | B4: Activo | C4: Dividendo bruto ($) | D4: Retención / impuestos ($) | E4: Otros cargos ($) | F4: Neto recibido ($) | G4: Reinvertido? | H4: Fuente / comprobante | I4: Nota
F5: =IF(C5="","",C5-IF(D5="",0,D5)-IF(E5="",0,E5))
F6: =IF(C6="","",C6-IF(D6="",0,D6)-IF(E6="",0,E6))
F7: =IF(C7="","",C7-IF(D7="",0,D7)-IF(E7="",0,E7))
F8: =IF(C8="","",C8-IF(D8="",0,D8)-IF(E8="",0,E8))
F9: =IF(C9="","",C9-IF(D9="",0,D9)-IF(E9="",0,E9))
F10: =IF(C10="","",C10-IF(D10="",0,D10)-IF(E10="",0,E10))
F11: =IF(C11="","",C11-IF(D11="",0,D11)-IF(E11="",0,E11))
F12: =IF(C12="","",C12-IF(D12="",0,D12)-IF(E12="",0,E12))
F13: =IF(C13="","",C13-IF(D13="",0,D13)-IF(E13="",0,E13))
F14: =IF(C14="","",C14-IF(D14="",0,D14)-IF(E14="",0,E14))
F15: =IF(C15="","",C15-IF(D15="",0,D15)-IF(E15="",0,E15))
F16: =IF(C16="","",C16-IF(D16="",0,D16)-IF(E16="",0,E16))
... F204: =IF(C204="","",C204-IF(D204="",0,D204)-IF(E204="",0,E204))

Sheet Precios
A1: HISTÓRICO DE PRECIOS
A2: No reemplaces precios anteriores. Agrega una fila nueva por activo y fecha; Posiciones usa la última fila registrada para cada ticker.
A4: Fecha | B4: Activo | C4: Precio ($) | D4: Fuente | E4: Nota
A5: 46314 | B5: IVV | C5: 770.89 | D5: Hapi | E5: Precio mostrado por Hapi en la última captura
A6: 46314 | B6: BTC | C6: 81990.93 | D6: Hapi | E6: Precio mostrado por Hapi en la última captura
A7: 46314 | B7: VXUS | C7: 83.38 | D7: Hapi

Sheet Posiciones
A1: POSICIONES POR ACTIVO
A2: Vista calculada. No edites cantidades ni costos. Cantidad actual = compras - ventas + referidos. Precio = último registro histórico.
A4: Activo | B4: Tipo | C4: Comprado | D4: Vendido | E4: Referido | F4: Cantidad actual | G4: Monto compras ($) | H4: Comisiones compras ($) | I4: Neto ventas ($) | J4: Costo total compras ($) | K4: Costo promedio compra ($) | L4: Fecha último precio | M4: Precio actual ($) | N4: Valor actual posición ($) | O4: Costo base actual estimado ($) | P4: G/P no realizada compras ($) | Q4: Resultado patrimonial vs bolsillo ($) | R4: Rentabilidad no realizada | S4: Peso actual | T4: Objetivo | U4: Diferencia
A5: =IF(Activos!A5="","",Activos!A5) -> IVV | B5: =IF(A5="","",Activos!C5) -> ETF | C5: =IF(A5="","",SUMIFS(Transacciones!$E$5:$E$1004,Transacciones!$B$5:$B$1004,A5,Transacciones!$D$5:$D$1004,"COMPRA")) -> 0.54308 | D5: =IF(A5="","",SUMIFS(Transacciones!$E$5:$E$1004,Transacciones!$B$5:$B$1004,A5,Transacciones!$D$5:$D$1004,"VENTA")) -> 0 | E5: =IF(A5="","",SUMIF(Referidos!$C$5:$C$204,A5,Referidos!$D$5:$D$204)) -> 0 | F5: =IF(A5="","",C5-D5+E5) -> 0.54308 | G5: =IF(A5="","",SUMIFS(Transacciones!$G$5:$G$1004,Transacciones!$B$5:$B$1004,A5,Transacciones!$D$5:$D$1004,"COMPRA")) -> 420.07 | H5: =IF(A5="","",SUMIFS(Transacciones!$H$5:$H$1004,Transacciones!$B$5:$B$1004,A5,Transacciones!$D$5:$D$1004,"COMPRA")) -> 0.45 | I5: =IF(A5="","",SUMIFS(Transacciones!$I$5:$I$1004,Transacciones!$B$5:$B$1004,A5,Transacciones!$D$5:$D$1004,"VENTA")) -> 0 | J5: =IF(A5="","",G5+H5) -> 420.52 | K5: =IFERROR(J5/C5,0) -> 774.32422 | L5: =IF(A5="","",IFERROR(LOOKUP(2,1/(Precios!$B$5:$B$2004=A5),Precios!$A$5:$A$2004),"")) -> 46314 | M5: =IF(A5="","",IFERROR(LOOKUP(2,1/(Precios!$B$5:$B$2004=A5),Precios!$C$5:$C$2004),0)) -> 770.89 | N5: =IF(A5="","",F5*M5) -> 418.65494 | O5: =IF(A5="","",MAX(C5-D5,0)*K5) -> 420.52 | P5: =IF(A5="","",MAX(C5-D5,0)*M5-O5) -> -1.8650588 | Q5: =IF(A5="","",N5-O5) -> -1.8650588 | R5: =IFERROR(P5/O5,0) -> -0.0044351251 | S5: =IFERROR(N5/SUM($N$5:$N$104),0) -> 0.83268855 | T5: =IF(A5="","",Activos!E5) -> 0.85 | U5: =IF(A5="","",S5-T5) -> -0.017311453
A6: =IF(Activos!A6="","",Activos!A6) -> VXUS | B6: =IF(A6="","",Activos!C6) -> ETF | C6: =IF(A6="","",SUMIFS(Transacciones!$E$5:$E$1004,Transacciones!$B$5:$B$1004,A6,Transacciones!$D$5:$D$1004,"COMPRA")) -> 0.67273 | D6: =IF(A6="","",SUMIFS(Transacciones!$E$5:$E$1004,Transacciones!$B$5:$B$1004,A6,Transacciones!$D$5:$D$1004,"VENTA")) -> 0 | E6: =IF(A6="","",SUMIF(Referidos!$C$5:$C$204,A6,Referidos!$D$5:$D$204)) -> 0 | F6: =IF(A6="","",C6-D6+E6) -> 0.67273 | G6: =IF(A6="","",SUMIFS(Transacciones!$G$5:$G$1004,Transacciones!$B$5:$B$1004,A6,Transacciones!$D$5:$D$1004,"COMPRA")) -> 56 | H6: =IF(A6="","",SUMIFS(Transacciones!$H$5:$H$1004,Transacciones!$B$5:$B$1004,A6,Transacciones!$D$5:$D$1004,"COMPRA")) -> 0.3 | I6: =IF(A6="","",SUMIFS(Transacciones!$I$5:$I$1004,Transacciones!$B$5:$B$1004,A6,Transacciones!$D$5:$D$1004,"VENTA")) -> 0 | J6: =IF(A6="","",G6+H6) -> 56.3 | K6: =IFERROR(J6/C6,0) -> 83.68885 | L6: =IF(A6="","",IFERROR(LOOKUP(2,1/(Precios!$B$5:$B$2004=A6),Precios!$A$5:$A$2004),"")) -> 46314 | M6: =IF(A6="","",IFERROR(LOOKUP(2,1/(Precios!$B$5:$B$2004=A6),Precios!$C$5:$C$2004),0)) -> 83.38 | N6: =IF(A6="","",F6*M6) -> 56.092227 | O6: =IF(A6="","",MAX(C6-D6,0)*K6) -> 56.3 | P6: =IF(A6="","",MAX(C6-D6,0)*M6-O6) -> -0.2077726 | Q6: =IF(A6="","",N6-O6) -> -0.2077726 | R6: =IFERROR(P6/O6,0) -> -0.0036904547 | S6: =IFERROR(N6/SUM($N$5:$N$104),0) -> 0.11156528 | T6: =IF(A6="","",Activos!E6) -> 0.1 | U6: =IF(A6="","",S6-T6) -> 0.011565279
A7: =IF(Activos!A7="","",Activos!A7) -> BTC | B7: =IF(A7="","",Activos!C7) -> CRIPTO | C7: =IF(A7="","",SUMIFS(Transacciones!$E$5:$E$1004,Transacciones!$B$5:$B$1004,A7,Transacciones!$D$5:$D$1004,"COMPRA")) -> 0.00032988 | D7: =IF(A7="","",SUMIFS(Transacciones!$E$5:$E$1004,Transacciones!$B$5:$B$1004,A7,Transacciones!$D$5:$D$1004,"VENTA")) -> 0 | E7: =IF(A7="","",SUMIF(Referidos!$C$5:$C$204,A7,Referidos!$D$5:$D$204)) -> 1.196e-05 | F7: =IF(A7="","",C7-D7+E7) -> 0.00034184 | G7: =IF(A7="","",SUMIFS(Transacciones!$G$5:$G$1004,Transacciones!$B$5:$B$1004,A7,Transacciones!$D$5:$D$1004,"COMPRA")) -> 27 | H7: =IF(A7="","",SUMIFS(Transacciones!$H$5:$H$1004,Transacciones!$B$5:$B$1004,A7,Transacciones!$D$5:$D$1004,"COMPRA")) -> 0.27 | I7: =IF(A7="","",SUMIFS(Transacciones!$I$5:$I$1004,Transacciones!$B$5:$B$1004,A7,Transacciones!$D$5:$D$1004,"VENTA")) -> 0 | J7: =IF(A7="","",G7+H7) -> 27.27 | K7: =IFERROR(J7/C7,0) -> 82666.424 | L7: =IF(A7="","",IFERROR(LOOKUP(2,1/(Precios!$B$5:$B$2004=A7),Precios!$A$5:$A$2004),"")) -> 46314 | M7: =IF(A7="","",IFERROR(LOOKUP(2,1/(Precios!$B$5:$B$2004=A7),Precios!$C$5:$C$2004),0)) -> 81990.93 | N7: =IF(A7="","",F7*M7) -> 28.02778 | O7: =IF(A7="","",MAX(C7-D7,0)*K7) -> 27.27 | P7: =IF(A7="","",MAX(C7-D7,0)*M7-O7) -> -0.22283201 | Q7: =IF(A7="","",N7-O7) -> 0.75777951 | R7: =IFERROR(P7/O7,0) -> -0.0081713242 | S7: =IFERROR(N7/SUM($N$5:$N$104),0) -> 0.055746174 | T7: =IF(A7="","",Activos!E7) -> 0.05 | U7: =IF(A7="","",S7-T7) -> 0.0057461735
A8: =IF(Activos!A8="","",Activos!A8) | B8: =IF(A8="","",Activos!C8) | C8: =IF(A8="","",SUMIFS(Transacciones!$E$5:$E$1004,Transacciones!$B$5:$B$1004,A8,Transacciones!$D$5:$D$1004,"COMPRA")) | D8: =IF(A8="","",SUMIFS(Transacciones!$E$5:$E$1004,Transacciones!$B$5:$B$1004,A8,Transacciones!$D$5:$D$1004,"VENTA")) | E8: =IF(A8="","",SUMIF(Referidos!$C$5:$C$204,A8,Referidos!$D$5:$D$204)) | F8: =IF(A8="","",C8-D8+E8) | G8: =IF(A8="","",SUMIFS(Transacciones!$G$5:$G$1004,Transacciones!$B$5:$B$1004,A8,Transacciones!$D$5:$D$1004,"COMPRA")) | H8: =IF(A8="","",SUMIFS(Transacciones!$H$5:$H$1004,Transacciones!$B$5:$B$1004,A8,Transacciones!$D$5:$D$1004,"COMPRA")) | I8: =IF(A8="","",SUMIFS(Transacciones!$I$5:$I$1004,Transacciones!$B$5:$B$1004,A8,Transacciones!$D$5:$D$1004,"VENTA")) | J8: =IF(A8="","",G8+H8) | K8: =IFERROR(J8/C8,0) -> 0 | L8: =IF(A8="","",IFERROR(LOOKUP(2,1/(Precios!$B$5:$B$2004=A8),Precios!$A$5:$A$2004),"")) | M8: =IF(A8="","",IFERROR(LOOKUP(2,1/(Precios!$B$5:$B$2004=A8),Precios!$C$5:$C$2004),0)) | N8: =IF(A8="","",F8*M8) | O8: =IF(A8="","",MAX(C8-D8,0)*K8) | P8: =IF(A8="","",MAX(C8-D8,0)*M8-O8) | Q8: =IF(A8="","",N8-O8) | R8: =IFERROR(P8/O8,0) -> 0 | S8: =IFERROR(N8/SUM($N$5:$N$104),0) -> 0 | T8: =IF(A8="","",Activos!E8) | U8: =IF(A8="","",S8-T8)
A9: =IF(Activos!A9="","",Activos!A9) | B9: =IF(A9="","",Activos!C9) | C9: =IF(A9="","",SUMIFS(Transacciones!$E$5:$E$1004,Transacciones!$B$5:$B$1004,A9,Transacciones!$D$5:$D$1004,"COMPRA")) | D9: =IF(A9="","",SUMIFS(Transacciones!$E$5:$E$1004,Transacciones!$B$5:$B$1004,A9,Transacciones!$D$5:$D$1004,"VENTA")) | E9: =IF(A9="","",SUMIF(Referidos!$C$5:$C$204,A9,Referidos!$D$5:$D$204)) | F9: =IF(A9="","",C9-D9+E9) | G9: =IF(A9="","",SUMIFS(Transacciones!$G$5:$G$1004,Transacciones!$B$5:$B$1004,A9,Transacciones!$D$5:$D$1004,"COMPRA")) | H9: =IF(A9="","",SUMIFS(Transacciones!$H$5:$H$1004,Transacciones!$B$5:$B$1004,A9,Transacciones!$D$5:$D$1004,"COMPRA")) | I9: =IF(A9="","",SUMIFS(Transacciones!$I$5:$I$1004,Transacciones!$B$5:$B$1004,A9,Transacciones!$D$5:$D$1004,"VENTA")) | J9: =IF(A9="","",G9+H9) | K9: =IFERROR(J9/C9,0) -> 0 | L9: =IF(A9="","",IFERROR(LOOKUP(2,1/(Precios!$B$5:$B$2004=A9),Precios!$A$5:$A$2004),"")) | M9: =IF(A9="","",IFERROR(LOOKUP(2,1/(Precios!$B$5:$B$2004=A9),Precios!$C$5:$C$2004),0)) | N9: =IF(A9="","",F9*M9) | O9: =IF(A9="","",MAX(C9-D9,0)*K9) | P9: =IF(A9="","",MAX(C9-D9,0)*M9-O9) | Q9: =IF(A9="","",N9-O9) | R9: =IFERROR(P9/O9,0) -> 0 | S9: =IFERROR(N9/SUM($N$5:$N$104),0) -> 0 | T9: =IF(A9="","",Activos!E9) | U9: =IF(A9="","",S9-T9)
A10: =IF(Activos!A10="","",Activos!A10) | B10: =IF(A10="","",Activos!C10) | C10: =IF(A10="","",SUMIFS(Transacciones!$E$5:$E$1004,Transacciones!$B$5:$B$1004,A10,Transacciones!$D$5:$D$1004,"COMPRA")) | D10: =IF(A10="","",SUMIFS(Transacciones!$E$5:$E$1004,Transacciones!$B$5:$B$1004,A10,Transacciones!$D$5:$D$1004,"VENTA")) | E10: =IF(A10="","",SUMIF(Referidos!$C$5:$C$204,A10,Referidos!$D$5:$D$204)) | F10: =IF(A10="","",C10-D10+E10) | G10: =IF(A10="","",SUMIFS(Transacciones!$G$5:$G$1004,Transacciones!$B$5:$B$1004,A10,Transacciones!$D$5:$D$1004,"COMPRA")) | H10: =IF(A10="","",SUMIFS(Transacciones!$H$5:$H$1004,Transacciones!$B$5:$B$1004,A10,Transacciones!$D$5:$D$1004,"COMPRA")) | I10: =IF(A10="","",SUMIFS(Transacciones!$I$5:$I$1004,Transacciones!$B$5:$B$1004,A10,Transacciones!$D$5:$D$1004,"VENTA")) | J10: =IF(A10="","",G10+H10) | K10: =IFERROR(J10/C10,0) -> 0 | L10: =IF(A10="","",IFERROR(LOOKUP(2,1/(Precios!$B$5:$B$2004=A10),Precios!$A$5:$A$2004),"")) | M10: =IF(A10="","",IFERROR(LOOKUP(2,1/(Precios!$B$5:$B$2004=A10),Precios!$C$5:$C$2004),0)) | N10: =IF(A10="","",F10*M10) | O10: =IF(A10="","",MAX(C10-D10,0)*K10) | P10: =IF(A10="","",MAX(C10-D10,0)*M10-O10) | Q10: =IF(A10="","",N10-O10) | R10: =IFERROR(P10/O10,0) -> 0 | S10: =IFERROR(N10/SUM($N$5:$N$104),0) -> 0 | T10: =IF(A10="","",Activos!E10) | U10: =IF(A10="","",S10-T10)
A11: =IF(Activos!A11="","",Activos!A11) | B11: =IF(A11="","",Activos!C11) | C11: =IF(A11="","",SUMIFS(Transacciones!$E$5:$E$1004,Transacciones!$B$5:$B$1004,A11,Transacciones!$D$5:$D$1004,"COMPRA")) | D11: =IF(A11="","",SUMIFS(Transacciones!$E$5:$E$1004,Transacciones!$B$5:$B$1004,A11,Transacciones!$D$5:$D$1004,"VENTA")) | E11: =IF(A11="","",SUMIF(Referidos!$C$5:$C$204,A11,Referidos!$D$5:$D$204)) | F11: =IF(A11="","",C11-D11+E11) | G11: =IF(A11="","",SUMIFS(Transacciones!$G$5:$G$1004,Transacciones!$B$5:$B$1004,A11,Transacciones!$D$5:$D$1004,"COMPRA")) | H11: =IF(A11="","",SUMIFS(Transacciones!$H$5:$H$1004,Transacciones!$B$5:$B$1004,A11,Transacciones!$D$5:$D$1004,"COMPRA")) | I11: =IF(A11="","",SUMIFS(Transacciones!$I$5:$I$1004,Transacciones!$B$5:$B$1004,A11,Transacciones!$D$5:$D$1004,"VENTA")) | J11: =IF(A11="","",G11+H11) | K11: =IFERROR(J11/C11,0) -> 0 | L11: =IF(A11="","",IFERROR(LOOKUP(2,1/(Precios!$B$5:$B$2004=A11),Precios!$A$5:$A$2004),"")) | M11: =IF(A11="","",IFERROR(LOOKUP(2,1/(Precios!$B$5:$B$2004=A11),Precios!$C$5:$C$2004),0)) | N11: =IF(A11="","",F11*M11) | O11: =IF(A11="","",MAX(C11-D11,0)*K11) | P11: =IF(A11="","",MAX(C11-D11,0)*M11-O11) | Q11: =IF(A11="","",N11-O11) | R11: =IFERROR(P11/O11,0) -> 0 | S11: =IFERROR(N11/SUM($N$5:$N$104),0) -> 0 | T11: =IF(A11="","",Activos!E11) | U11: =IF(A11="","",S11-T11)
A12: =IF(Activos!A12="","",Activos!A12) | B12: =IF(A12="","",Activos!C12) | C12: =IF(A12="","",SUMIFS(Transacciones!$E$5:$E$1004,Transacciones!$B$5:$B$1004,A12,Transacciones!$D$5:$D$1004,"COMPRA")) | D12: =IF(A12="","",SUMIFS(Transacciones!$E$5:$E$1004,Transacciones!$B$5:$B$1004,A12,Transacciones!$D$5:$D$1004,"VENTA")) | E12: =IF(A12="","",SUMIF(Referidos!$C$5:$C$204,A12,Referidos!$D$5:$D$204)) | F12: =IF(A12="","",C12-D12+E12) | G12: =IF(A12="","",SUMIFS(Transacciones!$G$5:$G$1004,Transacciones!$B$5:$B$1004,A12,Transacciones!$D$5:$D$1004,"COMPRA")) | H12: =IF(A12="","",SUMIFS(Transacciones!$H$5:$H$1004,Transacciones!$B$5:$B$1004,A12,Transacciones!$D$5:$D$1004,"COMPRA")) | I12: =IF(A12="","",SUMIFS(Transacciones!$I$5:$I$1004,Transacciones!$B$5:$B$1004,A12,Transacciones!$D$5:$D$1004,"VENTA")) | J12: =IF(A12="","",G12+H12) | K12: =IFERROR(J12/C12,0) -> 0 | L12: =IF(A12="","",IFERROR(LOOKUP(2,1/(Precios!$B$5:$B$2004=A12),Precios!$A$5:$A$2004),"")) | M12: =IF(A12="","",IFERROR(LOOKUP(2,1/(Precios!$B$5:$B$2004=A12),Precios!$C$5:$C$2004),0)) | N12: =IF(A12="","",F12*M12) | O12: =IF(A12="","",MAX(C12-D12,0)*K12) | P12: =IF(A12="","",MAX(C12-D12,0)*M12-O12) | Q12: =IF(A12="","",N12-O12) | R12: =IFERROR(P12/O12,0) -> 0 | S12: =IFERROR(N12/SUM($N$5:$N$104),0) -> 0 | T12: =IF(A12="","",Activos!E12) | U12: =IF(A12="","",S12-T12)
A13: =IF(Activos!A13="","",Activos!A13) | B13: =IF(A13="","",Activos!C13) | C13: =IF(A13="","",SUMIFS(Transacciones!$E$5:$E$1004,Transacciones!$B$5:$B$1004,A13,Transacciones!$D$5:$D$1004,"COMPRA")) | D13: =IF(A13="","",SUMIFS(Transacciones!$E$5:$E$1004,Transacciones!$B$5:$B$1004,A13,Transacciones!$D$5:$D$1004,"VENTA")) | E13: =IF(A13="","",SUMIF(Referidos!$C$5:$C$204,A13,Referidos!$D$5:$D$204)) | F13: =IF(A13="","",C13-D13+E13) | G13: =IF(A13="","",SUMIFS(Transacciones!$G$5:$G$1004,Transacciones!$B$5:$B$1004,A13,Transacciones!$D$5:$D$1004,"COMPRA")) | H13: =IF(A13="","",SUMIFS(Transacciones!$H$5:$H$1004,Transacciones!$B$5:$B$1004,A13,Transacciones!$D$5:$D$1004,"COMPRA")) | I13: =IF(A13="","",SUMIFS(Transacciones!$I$5:$I$1004,Transacciones!$B$5:$B$1004,A13,Transacciones!$D$5:$D$1004,"VENTA")) | J13: =IF(A13="","",G13+H13) | K13: =IFERROR(J13/C13,0) -> 0 | L13: =IF(A13="","",IFERROR(LOOKUP(2,1/(Precios!$B$5:$B$2004=A13),Precios!$A$5:$A$2004),"")) | M13: =IF(A13="","",IFERROR(LOOKUP(2,1/(Precios!$B$5:$B$2004=A13),Precios!$C$5:$C$2004),0)) | N13: =IF(A13="","",F13*M13) | O13: =IF(A13="","",MAX(C13-D13,0)*K13) | P13: =IF(A13="","",MAX(C13-D13,0)*M13-O13) | Q13: =IF(A13="","",N13-O13) | R13: =IFERROR(P13/O13,0) -> 0 | S13: =IFERROR(N13/SUM($N$5:$N$104),0) -> 0 | T13: =IF(A13="","",Activos!E13) | U13: =IF(A13="","",S13-T13)
A14: =IF(Activos!A14="","",Activos!A14) | B14: =IF(A14="","",Activos!C14) | C14: =IF(A14="","",SUMIFS(Transacciones!$E$5:$E$1004,Transacciones!$B$5:$B$1004,A14,Transacciones!$D$5:$D$1004,"COMPRA")) | D14: =IF(A14="","",SUMIFS(Transacciones!$E$5:$E$1004,Transacciones!$B$5:$B$1004,A14,Transacciones!$D$5:$D$1004,"VENTA")) | E14: =IF(A14="","",SUMIF(Referidos!$C$5:$C$204,A14,Referidos!$D$5:$D$204)) | F14: =IF(A14="","",C14-D14+E14) | G14: =IF(A14="","",SUMIFS(Transacciones!$G$5:$G$1004,Transacciones!$B$5:$B$1004,A14,Transacciones!$D$5:$D$1004,"COMPRA")) | H14: =IF(A14="","",SUMIFS(Transacciones!$H$5:$H$1004,Transacciones!$B$5:$B$1004,A14,Transacciones!$D$5:$D$1004,"COMPRA")) | I14: =IF(A14="","",SUMIFS(Transacciones!$I$5:$I$1004,Transacciones!$B$5:$B$1004,A14,Transacciones!$D$5:$D$1004,"VENTA")) | J14: =IF(A14="","",G14+H14) | K14: =IFERROR(J14/C14,0) -> 0 | L14: =IF(A14="","",IFERROR(LOOKUP(2,1/(Precios!$B$5:$B$2004=A14),Precios!$A$5:$A$2004),"")) | M14: =IF(A14="","",IFERROR(LOOKUP(2,1/(Precios!$B$5:$B$2004=A14),Precios!$C$5:$C$2004),0)) | N14: =IF(A14="","",F14*M14) | O14: =IF(A14="","",MAX(C14-D14,0)*K14) | P14: =IF(A14="","",MAX(C14-D14,0)*M14-O14) | Q14: =IF(A14="","",N14-O14) | R14: =IFERROR(P14/O14,0) -> 0 | S14: =IFERROR(N14/SUM($N$5:$N$104),0) -> 0 | T14: =IF(A14="","",Activos!E14) | U14: =IF(A14="","",S14-T14)
A15: =IF(Activos!A15="","",Activos!A15) | B15: =IF(A15="","",Activos!C15) | C15: =IF(A15="","",SUMIFS(Transacciones!$E$5:$E$1004,Transacciones!$B$5:$B$1004,A15,Transacciones!$D$5:$D$1004,"COMPRA")) | D15: =IF(A15="","",SUMIFS(Transacciones!$E$5:$E$1004,Transacciones!$B$5:$B$1004,A15,Transacciones!$D$5:$D$1004,"VENTA")) | E15: =IF(A15="","",SUMIF(Referidos!$C$5:$C$204,A15,Referidos!$D$5:$D$204)) | F15: =IF(A15="","",C15-D15+E15) | G15: =IF(A15="","",SUMIFS(Transacciones!$G$5:$G$1004,Transacciones!$B$5:$B$1004,A15,Transacciones!$D$5:$D$1004,"COMPRA")) | H15: =IF(A15="","",SUMIFS(Transacciones!$H$5:$H$1004,Transacciones!$B$5:$B$1004,A15,Transacciones!$D$5:$D$1004,"COMPRA")) | I15: =IF(A15="","",SUMIFS(Transacciones!$I$5:$I$1004,Transacciones!$B$5:$B$1004,A15,Transacciones!$D$5:$D$1004,"VENTA")) | J15: =IF(A15="","",G15+H15) | K15: =IFERROR(J15/C15,0) -> 0 | L15: =IF(A15="","",IFERROR(LOOKUP(2,1/(Precios!$B$5:$B$2004=A15),Precios!$A$5:$A$2004),"")) | M15: =IF(A15="","",IFERROR(LOOKUP(2,1/(Precios!$B$5:$B$2004=A15),Precios!$C$5:$C$2004),0)) | N15: =IF(A15="","",F15*M15) | O15: =IF(A15="","",MAX(C15-D15,0)*K15) | P15: =IF(A15="","",MAX(C15-D15,0)*M15-O15) | Q15: =IF(A15="","",N15-O15) | R15: =IFERROR(P15/O15,0) -> 0 | S15: =IFERROR(N15/SUM($N$5:$N$104),0) -> 0 | T15: =IF(A15="","",Activos!E15) | U15: =IF(A15="","",S15-T15)
A16: =IF(Activos!A16="","",Activos!A16) | B16: =IF(A16="","",Activos!C16) | C16: =IF(A16="","",SUMIFS(Transacciones!$E$5:$E$1004,Transacciones!$B$5:$B$1004,A16,Transacciones!$D$5:$D$1004,"COMPRA")) | D16: =IF(A16="","",SUMIFS(Transacciones!$E$5:$E$1004,Transacciones!$B$5:$B$1004,A16,Transacciones!$D$5:$D$1004,"VENTA")) | E16: =IF(A16="","",SUMIF(Referidos!$C$5:$C$204,A16,Referidos!$D$5:$D$204)) | F16: =IF(A16="","",C16-D16+E16) | G16: =IF(A16="","",SUMIFS(Transacciones!$G$5:$G$1004,Transacciones!$B$5:$B$1004,A16,Transacciones!$D$5:$D$1004,"COMPRA")) | H16: =IF(A16="","",SUMIFS(Transacciones!$H$5:$H$1004,Transacciones!$B$5:$B$1004,A16,Transacciones!$D$5:$D$1004,"COMPRA")) | I16: =IF(A16="","",SUMIFS(Transacciones!$I$5:$I$1004,Transacciones!$B$5:$B$1004,A16,Transacciones!$D$5:$D$1004,"VENTA")) | J16: =IF(A16="","",G16+H16) | K16: =IFERROR(J16/C16,0) -> 0 | L16: =IF(A16="","",IFERROR(LOOKUP(2,1/(Precios!$B$5:$B$2004=A16),Precios!$A$5:$A$2004),"")) | M16: =IF(A16="","",IFERROR(LOOKUP(2,1/(Precios!$B$5:$B$2004=A16),Precios!$C$5:$C$2004),0)) | N16: =IF(A16="","",F16*M16) | O16: =IF(A16="","",MAX(C16-D16,0)*K16) | P16: =IF(A16="","",MAX(C16-D16,0)*M16-O16) | Q16: =IF(A16="","",N16-O16) | R16: =IFERROR(P16/O16,0) -> 0 | S16: =IFERROR(N16/SUM($N$5:$N$104),0) -> 0 | T16: =IF(A16="","",Activos!E16) | U16: =IF(A16="","",S16-T16)
... A104: =IF(Activos!A104="","",Activos!A104) | B104: =IF(A104="","",Activos!C104) | C104: =IF(A104="","",SUMIFS(Transacciones!$E$5:$E$1004,Transacciones!$B$5:$B$1004,A104,Transacciones!$D$5:$D$1004,"COMPRA")) | D104: =IF(A104="","",SUMIFS(Transacciones!$E$5:$E$1004,Transacciones!$B$5:$B$1004,A104,Transacciones!$D$5:$D$1004,"VENTA")) | E104: =IF(A104="","",SUMIF(Referidos!$C$5:$C$204,A104,Referidos!$D$5:$D$204)) | F104: =IF(A104="","",C104-D104+E104) | G104: =IF(A104="","",SUMIFS(Transacciones!$G$5:$G$1004,Transacciones!$B$5:$B$1004,A104,Transacciones!$D$5:$D$1004,"COMPRA")) | H104: =IF(A104="","",SUMIFS(Transacciones!$H$5:$H$1004,Transacciones!$B$5:$B$1004,A104,Transacciones!$D$5:$D$1004,"COMPRA")) | I104: =IF(A104="","",SUMIFS(Transacciones!$I$5:$I$1004,Transacciones!$B$5:$B$1004,A104,Transacciones!$D$5:$D$1004,"VENTA")) | J104: =IF(A104="","",G104+H104) | K104: =IFERROR(J104/C104,0) -> 0 | L104: =IF(A104="","",IFERROR(LOOKUP(2,1/(Precios!$B$5:$B$2004=A104),Precios!$A$5:$A$2004),"")) | M104: =IF(A104="","",IFERROR(LOOKUP(2,1/(Precios!$B$5:$B$2004=A104),Precios!$C$5:$C$2004),0)) | N104: =IF(A104="","",F104*M104) | O104: =IF(A104="","",MAX(C104-D104,0)*K104) | P104: =IF(A104="","",MAX(C104-D104,0)*M104-O104) | Q104: =IF(A104="","",N104-O104) | R104: =IFERROR(P104/O104,0) -> 0 | S104: =IFERROR(N104/SUM($N$5:$N$104),0) -> 0 | T104: =IF(A104="","",Activos!E104) | U104: =IF(A104="","",S104-T104)

Sheet Rendimiento
A1: HISTÓRICO DE RENDIMIENTO / SNAPSHOTS
A2: Cada fila conserva una fotografía histórica. Copia valores actuales y pégalos como valores; no enlaces el histórico a precios futuros.
A4: Fecha | B4: Aporte bolsillo acumulado ($) | C4: Neto broker acumulado ($) | D4: Costos fondeo ($) | E4: Comisiones acumuladas ($) | F4: Efectivo ($) | G4: Valor posiciones ($) | H4: Valor referidos ($) | I4: Valor total ($) | J4: Resultado vs bolsillo ($) | K4: Rentabilidad vs bolsillo (%) | L4: Nota
A5: 46314 | B5: 375 | C5: 363.55 | D5: 11.45 | E5: 0.62 | F5: 1.86 | G5: 359.4633 | H5: 0.98061152 | I5: 362.30391 | J5: =IF(OR(I5="",B5=""),"",I5-B5) -> -12.69609 | K5: =IFERROR(J5/B5,0) -> -0.033856239 | L5: Migrado desde V3
J6: =IF(OR(I6="",B6=""),"",I6-B6) | K6: =IFERROR(J6/B6,0) -> 0
J7: =IF(OR(I7="",B7=""),"",I7-B7) | K7: =IFERROR(J7/B7,0) -> 0
J8: =IF(OR(I8="",B8=""),"",I8-B8) | K8: =IFERROR(J8/B8,0) -> 0
J9: =IF(OR(I9="",B9=""),"",I9-B9) | K9: =IFERROR(J9/B9,0) -> 0
J10: =IF(OR(I10="",B10=""),"",I10-B10) | K10: =IFERROR(J10/B10,0) -> 0
J11: =IF(OR(I11="",B11=""),"",I11-B11) | K11: =IFERROR(J11/B11,0) -> 0
J12: =IF(OR(I12="",B12=""),"",I12-B12) | K12: =IFERROR(J12/B12,0) -> 0
J13: =IF(OR(I13="",B13=""),"",I13-B13) | K13: =IFERROR(J13/B13,0) -> 0
J14: =IF(OR(I14="",B14=""),"",I14-B14) | K14: =IFERROR(J14/B14,0) -> 0
J15: =IF(OR(I15="",B15=""),"",I15-B15) | K15: =IFERROR(J15/B15,0) -> 0
J16: =IF(OR(I16="",B16=""),"",I16-B16) | K16: =IFERROR(J16/B16,0) -> 0
J17: =IF(OR(I17="",B17=""),"",I17-B17) | K17: =IFERROR(J17/B17,0) -> 0
... J504: =IF(OR(I504="",B504=""),"",I504-B504) | K504: =IFERROR(J504/B504,0) -> 0
